Workbook

Sheet ACCUEIL
A1: GESTION RESTAURANT - TABLEAU DE BORD
A3: Bienvenue dans votre outil de gestion automatisé.
A5: UTILISATION RAPIDE :
A6: 1. PLATS : Vérifiez votre carte et prix (automatique).
A7: 2. STOCK_CUISINE : Saisissez vos entrées de marchandises.
A8: 3. VENTES : Enregistrez chaque vente (liste déroulante).
A9: 4. FOURNISSEURS : Passez vos commandes.
A10: 5. INVENTAIRES : Saisissez vos comptes réels.
A12: TOUT LE RESTE (DASHBOARD, RÉCAPITULATIFS, COÛTS) EST AUTOMATIQUE !
B15: ➡ ALLER AUX VENTES
B17: ➡ ALLER AU STOCK
B19: ➡ ALLER AU DASHBOARD
B21: ➡ ALLER AUX FOURNISSEURS
B23: ➡ ALLER AUX INVENTAIRES

Sheet PLATS
A1: Plat | B1: Variante | C1: Prix (FCFA) | D1: Observation | E1: Catégorie
A2: Burger | B2: Chicken Burger | C2: 3500 | E2: Burger
A3: Burger | B3: Burger Normal | C3: 3500 | E3: Burger
A4: Brochette de porc | C4: 3000 | D4: Trois Brochettes | E4: Brochette
A5: Ndole Royal | B5: Viande | C5: 3500 | E5: Plat
A6: Ndole Royal | B6: Poisson fumé | C6: 3500 | E6: Plat
A7: Ndole Royal | B7: Crevette | C7: 3500 | E7: Plat
A8: Ndole Royal | B8: Portion | C8: 1000 | E8: Plat
A9: Free Rice | B9: Crevette | C9: 4000 | E9: Riz
A10: Free Rice | B10: Poulet | C10: 3500 | E10: Riz
A11: Poulet | B11: Pané | C11: 3500 | D11: un quart | E11: Poulet
A12: Poulet | B12: Braisé | C12: 3000 | D12: un quart | E12: Poulet
A13: Porc | B13: Moutarde | C13: 3500 | E13: Porc
A14: Porc | B14: Braisé | C14: 3000 | E14: Porc
A15: Gambas | B15: À l'ail | C15: 6500 | D15: 6500/10000 | E15: FruitMer
A16: Gambas | B16: Braisé | C16: 6500 | D16: 6500/10000 | E16: FruitMer
A17: Saucisse | C17: 3500 | D17: x 2 | E17: Charcuterie
A18: Tacos | B18: Poulet | C18: 4000 | E18: Tacos
A19: Tacos | B19: Viande | C19: 3500 | E19: Tacos
A20: Pizza | B20: Seven - Solo | C20: 3500 | E20: Pizza
A21: Pizza | B21: Seven - Duo | C21: 7000 | E21: Pizza
A22: Pizza | B22: Seven - Familiale | C22: 13500 | E22: Pizza
A23: Pizza | B23: Spices Bonita - Solo | C23: 3000 | E23: Pizza
A24: Pizza | B24: Spices Bonita - Duo | C24: 6000 | E24: Pizza
A25: Pizza | B25: Spices Bonita - Familiale | C25: 12000 | E25: Pizza
A26: Pizza | B26: Bimbia Cheese - Solo | C26: 2500 | E26: Pizza
A27: Pizza | B27: Bimbia Cheese - Duo | C27: 4500 | E27: Pizza
A28: Pizza | B28: Bimbia Cheese - Familiale | C28: 10000 | E28: Pizza
A29: Pizza | B29: Végétarienne - Solo | C29: 2500 | E29: Pizza
... A31: Pizza | B31: Végétarienne - Familiale | C31: 11000 | E31: Pizza
A32: Poisson | B32: Carpe | C32: 5000 | D32: 5000-8000 | E32: Poisson
A33: Poisson | B33: Sole | C33: 9000 | D33: 9000-11000 | E33: Poisson
A34: Poisson | B34: Bar | C34: 7000 | D34: 7000-10000 | E34: Poisson
A35: Jus Naturel / Bissap | B35: Litre | C35: 2000 | D35: Conso à 1000 | E35: Boisson
A36: Jus Naturel / Bissap | B36: Fruit de Saison | C36: 3500 | D36: En litre | E36: Boisson
A37: Accompagnement | B37: Riz | C37: 0 | D37: Pour chaque plat | E37: Accompagnement
A38: Accompagnement | B38: Frites | C38: 0 | D38: Pour chaque plat | E38: Accompagnement
A39: Accompagnement | B39: Plantain | C39: 0 | D39: Pour chaque plat | E39: Accompagnement
A40: Accompagnement | B40: Miondo | C40: 0 | D40: Pour chaque plat | E40: Accompagnement
A41: Pack Brise Snack | B41: Deux morceaux de poulet, portion de frit, un verre de jus | C41: 4000 | E41: Pack
...

Sheet STOCK_CUISINE
A1: Catégorie | B1: Article | C1: Unité | D1: Stock Initial | E1: Entrées | F1: Sorties | G1: Stock Final | H1: Coût Unitaire | I1: Valeur Stock | J1: Statut
A2: Viandes | B2: Poulet entier | C2: Unité | D2: 0 | E2: 0 | F2: 0 | G2: =D2+E2-F2 | H2: 0 | I2: =G2*H2 | J2: =IF(G2=0, "RUPTURE", IF(G2<5, "CRITIQUE", IF(G2<10, "ATTENTION", "OK")))
A3: Viandes | B3: Aile de Poulet | C3: Unité | D3: 0 | E3: 0 | F3: 0 | G3: =D3+E3-F3 | H3: 0 | I3: =G3*H3 | J3: =IF(G3=0, "RUPTURE", IF(G3<5, "CRITIQUE", IF(G3<10, "ATTENTION", "OK")))
A4: Viandes | B4: Cuisse de poulet | C4: Unité | D4: 0 | E4: 0 | F4: 0 | G4: =D4+E4-F4 | H4: 0 | I4: =G4*H4 | J4: =IF(G4=0, "RUPTURE", IF(G4<5, "CRITIQUE", IF(G4<10, "ATTENTION", "OK")))
A5: Viandes | B5: Bœuf | C5: Unité | D5: 0 | E5: 0 | F5: 0 | G5: =D5+E5-F5 | H5: 0 | I5: =G5*H5 | J5: =IF(G5=0, "RUPTURE", IF(G5<5, "CRITIQUE", IF(G5<10, "ATTENTION", "OK")))
A6: Viandes | B6: Porc | C6: Unité | D6: 0 | E6: 0 | F6: 0 | G6: =D6+E6-F6 | H6: 0 | I6: =G6*H6 | J6: =IF(G6=0, "RUPTURE", IF(G6<5, "CRITIQUE", IF(G6<10, "ATTENTION", "OK")))
A7: Poissons | B7: Carpe | C7: Unité | D7: 0 | E7: 0 | F7: 0 | G7: =D7+E7-F7 | H7: 0 | I7: =G7*H7 | J7: =IF(G7=0, "RUPTURE", IF(G7<5, "CRITIQUE", IF(G7<10, "ATTENTION", "OK")))
A8: Poissons | B8: Sole | C8: Unité | D8: 0 | E8: 0 | F8: 0 | G8: =D8+E8-F8 | H8: 0 | I8: =G8*H8 | J8: =IF(G8=0, "RUPTURE", IF(G8<5, "CRITIQUE", IF(G8<10, "ATTENTION", "OK")))
A9: Poissons | B9: Bar | C9: Unité | D9: 0 | E9: 0 | F9: 0 | G9: =D9+E9-F9 | H9: 0 | I9: =G9*H9 | J9: =IF(G9=0, "RUPTURE", IF(G9<5, "CRITIQUE", IF(G9<10, "ATTENTION", "OK")))
A10: Poissons | B10: Gambas | C10: Unité | D10: 0 | E10: 0 | F10: 0 | G10: =D10+E10-F10 | H10: 0 | I10: =G10*H10 | J10: =IF(G10=0, "RUPTURE", IF(G10<5, "CRITIQUE", IF(G10<10, "ATTENTION", "OK")))
A11: Poissons | B11: Crevette | C11: Unité | D11: 0 | E11: 0 | F11: 0 | G11: =D11+E11-F11 | H11: 0 | I11: =G11*H11 | J11: =IF(G11=0, "RUPTURE", IF(G11<5, "CRITIQUE", IF(G11<10, "ATTENTION", "OK")))
A12: Légumes | B12: Carottes | C12: Unité | D12: 0 | E12: 0 | F12: 0 | G12: =D12+E12-F12 | H12: 0 | I12: =G12*H12 | J12: =IF(G12=0, "RUPTURE", IF(G12<5, "CRITIQUE", IF(G12<10, "ATTENTION", "OK")))
A13: Légumes | B13: Tomates | C13: Unité | D13: 0 | E13: 0 | F13: 0 | G13: =D13+E13-F13 | H13: 0 | I13: =G13*H13 | J13: =IF(G13=0, "RUPTURE", IF(G13<5, "CRITIQUE", IF(G13<10, "ATTENTION", "OK")))
... A25: Boissons | B25: Soda | C25: Unité | D25: 0 | E25: 0 | F25: 0 | G25: =D25+E25-F25 | H25: 0 | I25: =G25*H25 | J25: =IF(G25=0, "RUPTURE", IF(G25<5, "CRITIQUE", IF(G25<10, "ATTENTION", "OK")))

Sheet VENTES
A1: SAISIE DES VENTES JOURNALIÈRES
A3: Date : | B3: 26/05/2026 | C3: Heure Début : | E3: Heure Fin :
A4: N° | B4: Plat Vendu (Choisir dans la liste) | C4: Quantité | D4: Prix Unitaire (Auto) | E4: Total Ligne (Auto) | F4: Observation
A5: 1 | D5: =IF(B5="", "", SUMIF(PLATS!A:A, B5, PLATS!C:C)) | E5: =IF(C5="", "", C5*D5)
A6: 2 | D6: =IF(B6="", "", SUMIF(PLATS!A:A, B6, PLATS!C:C)) | E6: =IF(C6="", "", C6*D6)
A7: 3 | D7: =IF(B7="", "", SUMIF(PLATS!A:A, B7, PLATS!C:C)) | E7: =IF(C7="", "", C7*D7)
A8: 4 | D8: =IF(B8="", "", SUMIF(PLATS!A:A, B8, PLATS!C:C)) | E8: =IF(C8="", "", C8*D8)
A9: 5 | D9: =IF(B9="", "", SUMIF(PLATS!A:A, B9, PLATS!C:C)) | E9: =IF(C9="", "", C9*D9)
A10: 6 | D10: =IF(B10="", "", SUMIF(PLATS!A:A, B10, PLATS!C:C)) | E10: =IF(C10="", "", C10*D10)
A11: 7 | D11: =IF(B11="", "", SUMIF(PLATS!A:A, B11, PLATS!C:C)) | E11: =IF(C11="", "", C11*D11)
A12: 8 | D12: =IF(B12="", "", SUMIF(PLATS!A:A, B12, PLATS!C:C)) | E12: =IF(C12="", "", C12*D12)
A13: 9 | D13: =IF(B13="", "", SUMIF(PLATS!A:A, B13, PLATS!C:C)) | E13: =IF(C13="", "", C13*D13)
A14: 10 | D14: =IF(B14="", "", SUMIF(PLATS!A:A, B14, PLATS!C:C)) | E14: =IF(C14="", "", C14*D14)
A15: 11 | D15: =IF(B15="", "", SUMIF(PLATS!A:A, B15, PLATS!C:C)) | E15: =IF(C15="", "", C15*D15)
A16: 12 | D16: =IF(B16="", "", SUMIF(PLATS!A:A, B16, PLATS!C:C)) | E16: =IF(C16="", "", C16*D16)
... A24: 20 | D24: =IF(B24="", "", SUMIF(PLATS!A:A, B24, PLATS!C:C)) | E24: =IF(C24="", "", C24*D24)
A26: TOTAL VENTES DU JOUR : | E26: =SUM(E5:E25)
A27: Nombre de plats vendus : | C27: =SUM(C5:C26)
A28: Panier Moyen : | C28: =IF(C27=0, 0, E26/C27)
A30: Validé par (Signature) :

Sheet RECAP_VENTES
A1: RÉCAPITULATIF AUTOMATIQUE DES VENTES
A2: Burger | B2: Quantité Totale Vendue | C2: =SUMIF(VENTES!B:B, "Burger", VENTES!E:E) | D2: Burger
A3: Burger | C3: =SUMIF(VENTES!B:B, "Burger", VENTES!E:E) | D3: Burger
A4: Brochette de porc | C4: =SUMIF(VENTES!B:B, "Brochette de porc", VENTES!E:E) | D4: Brochette
A5: Ndole Royal | C5: =SUMIF(VENTES!B:B, "Ndole Royal", VENTES!E:E) | D5: Plat
A6: Ndole Royal | C6: =SUMIF(VENTES!B:B, "Ndole Royal", VENTES!E:E) | D6: Plat
A7: Ndole Royal | C7: =SUMIF(VENTES!B:B, "Ndole Royal", VENTES!E:E) | D7: Plat
A8: Ndole Royal | C8: =SUMIF(VENTES!B:B, "Ndole Royal", VENTES!E:E) | D8: Plat
A9: Free Rice | C9: =SUMIF(VENTES!B:B, "Free Rice", VENTES!E:E) | D9: Riz
A10: Free Rice | C10: =SUMIF(VENTES!B:B, "Free Rice", VENTES!E:E) | D10: Riz
A11: Poulet | C11: =SUMIF(VENTES!B:B, "Poulet", VENTES!E:E) | D11: Poulet
A12: Poulet | C12: =SUMIF(VENTES!B:B, "Poulet", VENTES!E:E) | D12: Poulet
A13: Porc | C13: =SUMIF(VENTES!B:B, "Porc", VENTES!E:E) | D13: Porc
A14: Porc | C14: =SUMIF(VENTES!B:B, "Porc", VENTES!E:E) | D14: Porc
A15: Gambas | C15: =SUMIF(VENTES!B:B, "Gambas", VENTES!E:E) | D15: FruitMer
A16: Gambas | C16: =SUMIF(VENTES!B:B, "Gambas", VENTES!E:E) | D16: FruitMer
A17: Saucisse | C17: =SUMIF(VENTES!B:B, "Saucisse", VENTES!E:E) | D17: Charcuterie
A18: Tacos | C18: =SUMIF(VENTES!B:B, "Tacos", VENTES!E:E) | D18: Tacos
A19: Tacos | C19: =SUMIF(VENTES!B:B, "Tacos", VENTES!E:E) | D19: Tacos
A20: Pizza | C20: =SUMIF(VENTES!B:B, "Pizza", VENTES!E:E) | D20: Pizza
A21: Pizza | C21: =SUMIF(VENTES!B:B, "Pizza", VENTES!E:E) | D21: Pizza
A22: Pizza | C22: =SUMIF(VENTES!B:B, "Pizza", VENTES!E:E) | D22: Pizza
A23: Pizza | C23: =SUMIF(VENTES!B:B, "Pizza", VENTES!E:E) | D23: Pizza
A24: Pizza | C24: =SUMIF(VENTES!B:B, "Pizza", VENTES!E:E) | D24: Pizza
A25: Pizza | C25: =SUMIF(VENTES!B:B, "Pizza", VENTES!E:E) | D25: Pizza
A26: Pizza | C26: =SUMIF(VENTES!B:B, "Pizza", VENTES!E:E) | D26: Pizza
A27: Pizza | C27: =SUMIF(VENTES!B:B, "Pizza", VENTES!E:E) | D27: Pizza
A28: Pizza | C28: =SUMIF(VENTES!B:B, "Pizza", VENTES!E:E) | D28: Pizza
A29: Pizza | C29: =SUMIF(VENTES!B:B, "Pizza", VENTES!E:E) | D29: Pizza
A30: Pizza | C30: =SUMIF(VENTES!B:B, "Pizza", VENTES!E:E) | D30: Pizza
A31: Pizza | C31: =SUMIF(VENTES!B:B, "Pizza", VENTES!E:E) | D31: Pizza
A32: Poisson | C32: =SUMIF(VENTES!B:B, "Poisson", VENTES!E:E) | D32: Poisson
A33: Poisson | C33: =SUMIF(VENTES!B:B, "Poisson", VENTES!E:E) | D33: Poisson
A34: Poisson | C34: =SUMIF(VENTES!B:B, "Poisson", VENTES!E:E) | D34: Poisson
A35: Jus Naturel / Bissap | C35: =SUMIF(VENTES!B:B, "Jus Naturel / Bissap", VENTES!E:E) | D35: Boisson
A36: Jus Naturel / Bissap | C36: =SUMIF(VENTES!B:B, "Jus Naturel / Bissap", VENTES!E:E) | D36: Boisson
A37: Accompagnement | C37: =SUMIF(VENTES!B:B, "Accompagnement", VENTES!E:E) | D37: Accompagnement
A38: Accompagnement | C38: =SUMIF(VENTES!B:B, "Accompagnement", VENTES!E:E) | D38: Accompagnement
A39: Accompagnement | C39: =SUMIF(VENTES!B:B, "Accompagnement", VENTES!E:E) | D39: Accompagnement
A40: Accompagnement | C40: =SUMIF(VENTES!B:B, "Accompagnement", VENTES!E:E) | D40: Accompagnement
...

Sheet FOURNISSEURS
A1: ID | B1: Nom Fournisseur | C1: Contact | D1: Téléphone | E1: Produits Fournis | F1: Statut Commande | G1: Montant Dû
A2: 1 | B2: Fournisseur Viandes | C2: M. Dupont | D2: 690000000 | E2: Viandes, Porc | F2: Actif | G2: 0
A3: 2 | B3: Marché Légumes | C3: Mme Martin | D3: 690000001 | E3: Légumes, Fruits | F3: Actif | G3: 0
A4: 3 | B4: Grossiste Boissons | C4: Sodifa | D4: 690000002 | E4: Eau, Jus, Soda | F4: Actif | G4: 0
A5: 4 | B5: Epicerie Centrale | C5: Cash | D5: 690000003 | E5: Riz, Huile, Épices | F5: Actif | G5: 0
A8: HISTORIQUE DES COMMANDES
A9: Date | B9: Fournisseur | C9: Article | D9: Quantité | E9: Prix Unitaire | F9: Total | G9: Statut
F10: =E10*F10 | G10: En Attente
F11: =E11*F11 | G11: En Attente
F12: =E12*F12 | G12: En Attente
F13: =E13*F13 | G13: En Attente
F14: =E14*F14 | G14: En Attente

Sheet INVENTAIRES
A1: FICHE D'INVENTAIRE PÉRIODIQUE
A2: Article | B2: Catégorie | C2: Stock Théorique (Auto) | D2: Stock Réel (Saisir) | E2: Écart (Théorique - Réel) | F2: Valeur Écart
A3: Poulet entier | B3: Viandes | C3: =STOCK_CUISINE!G2 | E3: =C2-D2 | F3: =E2*STOCK_CUISINE!H2
A4: Aile de Poulet | B4: Viandes | C4: =STOCK_CUISINE!G3 | E4: =C3-D3 | F4: =E3*STOCK_CUISINE!H3
A5: Cuisse de poulet | B5: Viandes | C5: =STOCK_CUISINE!G4 | E5: =C4-D4 | F5: =E4*STOCK_CUISINE!H4
A6: Bœuf | B6: Viandes | C6: =STOCK_CUISINE!G5 | E6: =C5-D5 | F6: =E5*STOCK_CUISINE!H5
A7: Porc | B7: Viandes | C7: =STOCK_CUISINE!G6 | E7: =C6-D6 | F7: =E6*STOCK_CUISINE!H6
A8: Carpe | B8: Poissons | C8: =STOCK_CUISINE!G7 | E8: =C7-D7 | F8: =E7*STOCK_CUISINE!H7
A9: Sole | B9: Poissons | C9: =STOCK_CUISINE!G8 | E9: =C8-D8 | F9: =E8*STOCK_CUISINE!H8
A10: Bar | B10: Poissons | C10: =STOCK_CUISINE!G9 | E10: =C9-D9 | F10: =E9*STOCK_CUISINE!H9
A11: Gambas | B11: Poissons | C11: =STOCK_CUISINE!G10 | E11: =C10-D10 | F11: =E10*STOCK_CUISINE!H10
A12: Crevette | B12: Poissons | C12: =STOCK_CUISINE!G11 | E12: =C11-D11 | F12: =E11*STOCK_CUISINE!H11
A13: Carottes | B13: Légumes | C13: =STOCK_CUISINE!G12 | E13: =C12-D12 | F13: =E12*STOCK_CUISINE!H12
A14: Tomates | B14: Légumes | C14: =STOCK_CUISINE!G13 | E14: =C13-D13 | F14: =E13*STOCK_CUISINE!H13
... A20: Huile | B20: Epicerie | C20: =STOCK_CUISINE!G19 | E20: =C19-D19 | F20: =E19*STOCK_CUISINE!H19

Sheet DASHBOARD
A1: TABLEAU DE BORD ANALYTIQUE
A3: CA Du Jour | B3: =VENTES!E26 | D3: TOP 5 PLATS VENDUS (CA)
A5: Plats Vendus | B5: =VENTES!C27 | D5: Rang | E5: Plat | F5: CA Total
D6: 1 | E6: Top 1 (Auto) | F6: 0
A7: Panier Moyen | B7: =VENTES!C28 | D7: 2 | E7: Top 2 (Auto) | F7: 0
D8: 3 | E8: Top 3 (Auto) | F8: 0
A9: Alertes Stock | B9: =COUNTIF(STOCK_CUISINE!J:J, "CRITIQUE") + COUNTIF(STOCK_CUISINE!J:J, "RUPTURE") | D9: 4 | E9: Top 4 (Auto) | F9: 0
D10: 5 | E10: Top 5 (Auto) | F10: 0
A11: Valeur Stock | B11: =SUM(STOCK_CUISINE!I:I) | D11: ALERTE STOCKS CRITIQUES
A12: Rang | B12: Plat | C12: CA Total
A13: Article | B13: Stock Actuel | C13: Statut | D13: Voir onglet STOCK_CUISINE pour détails
